Workbook

Sheet Banco de Dados
A1: Data | B1: Funcionário | C1: Hora Início | D1: Hora Final | E1: Horas Trabalhadas | F1: Semana do Ano | G1: Mês | H1: Ano | I1: Dia da semana
A2: 46113 | B2: LEONILSON DOS SANTOS SILVA | C2: 0.33333333 | D2: 0.7352662 | E2: =IF(OR(C2="", D2=""), 0, (D2-C2)*24) -> 9.6463889 | F2: =WEEKNUM(A2) -> 14 | G2: =MONTH(A2) -> 4 | H2: =YEAR(A2) -> 2026 | I2: =WEEKDAY(A2) -> 4
A3: 46113 | B3: ALEX FERREIRA DOS SANTOS | C3: 0.33402778 | D3: 0.71550926 | E3: =IF(OR(C3="", D3=""), 0, (D3-C3)*24) -> 9.1555556 | F3: =WEEKNUM(A3) -> 14 | G3: =MONTH(A3) -> 4 | H3: =YEAR(A3) -> 2026 | I3: =WEEKDAY(A3) -> 4
A4: 46113 | B4: FABIO MANOEL NERI | C4: 0.33333333 | D4: 0.71704861 | E4: =IF(OR(C4="", D4=""), 0, (D4-C4)*24) -> 9.2091667 | F4: =WEEKNUM(A4) -> 14 | G4: =MONTH(A4) -> 4 | H4: =YEAR(A4) -> 2026 | I4: =WEEKDAY(A4) -> 4
A5: 46113 | B5: DAVID APOLINARIO FRANCISCO | C5: 0.3375 | D5: 0.73232639 | E5: =IF(OR(C5="", D5=""), 0, (D5-C5)*24) -> 9.4758333 | F5: =WEEKNUM(A5) -> 14 | G5: =MONTH(A5) -> 4 | H5: =YEAR(A5) -> 2026 | I5: =WEEKDAY(A5) -> 4
A6: 46114 | B6: LEONILSON DOS SANTOS SILVA | C6: 0.34027778 | D6: 0.69454861 | E6: =IF(OR(C6="", D6=""), 0, (D6-C6)*24) -> 8.5025 | F6: =WEEKNUM(A6) -> 14 | G6: =MONTH(A6) -> 4 | H6: =YEAR(A6) -> 2026 | I6: =WEEKDAY(A6) -> 5
A7: 46114 | B7: ALEX FERREIRA DOS SANTOS | C7: 0.33333333 | D7: 0.73061343 | E7: =IF(OR(C7="", D7=""), 0, (D7-C7)*24) -> 9.5347222 | F7: =WEEKNUM(A7) -> 14 | G7: =MONTH(A7) -> 4 | H7: =YEAR(A7) -> 2026 | I7: =WEEKDAY(A7) -> 5
A8: 46114 | B8: FABIO MANOEL NERI | C8: 0.33263889 | D8: 0.68552083 | E8: =IF(OR(C8="", D8=""), 0, (D8-C8)*24) -> 8.4691667 | F8: =WEEKNUM(A8) -> 14 | G8: =MONTH(A8) -> 4 | H8: =YEAR(A8) -> 2026 | I8: =WEEKDAY(A8) -> 5
A9: 46114 | B9: LUCAS OLIVEIRA DA SILVA | C9: 0.51597222 | D9: 0.74773148 | E9: =IF(OR(C9="", D9=""), 0, (D9-C9)*24) -> 5.5622222 | F9: =WEEKNUM(A9) -> 14 | G9: =MONTH(A9) -> 4 | H9: =YEAR(A9) -> 2026 | I9: =WEEKDAY(A9) -> 5
A10: 46114 | B10: DAVID APOLINARIO FRANCISCO | C10: 0.44583333 | D10: 0.54622685 | E10: =IF(OR(C10="", D10=""), 0, (D10-C10)*24) -> 2.4094444 | F10: =WEEKNUM(A10) -> 14 | G10: =MONTH(A10) -> 4 | H10: =YEAR(A10) -> 2026 | I10: =WEEKDAY(A10) -> 5
A11: 46115 | B11: ALEX FERREIRA DOS SANTOS | C11: 0.41597222 | D11: 0.64650463 | E11: =IF(OR(C11="", D11=""), 0, (D11-C11)*24) -> 5.5327778 | F11: =WEEKNUM(A11) -> 14 | G11: =MONTH(A11) -> 4 | H11: =YEAR(A11) -> 2026 | I11: =WEEKDAY(A11) -> 6
A12: 46116 | B12: ALEX FERREIRA DOS SANTOS | C12: 0.33194444 | D12: 0.83699074 | E12: =IF(OR(C12="", D12=""), 0, (D12-C12)*24) -> 12.121111 | F12: =WEEKNUM(A12) -> 14 | G12: =MONTH(A12) -> 4 | H12: =YEAR(A12) -> 2026 | I12: =WEEKDAY(A12) -> 7
A13: 46116 | B13: LUCAS OLIVEIRA DA SILVA | C13: 0.3625 | D13: 0.66784722 | E13: =IF(OR(C13="", D13=""), 0, (D13-C13)*24) -> 7.3283333 | F13: =WEEKNUM(A13) -> 14 | G13: =MONTH(A13) -> 4 | H13: =YEAR(A13) -> 2026 | I13: =WEEKDAY(A13) -> 7
... A171: 46151 | B171: FELIPE MONTEIRO BARROSO DE ANDRADE | C171: 0.34097222 | D171: 0.67532407 | E171: =IF(OR(C171="", D171=""), 0, (D171-C171)*24) -> 8.0244444 | F171: =WEEKNUM(A171) -> 19 | G171: =MONTH(A171) -> 5 | H171: =YEAR(A171) -> 2026 | I171: =WEEKDAY(A171) -> 7
A172: 46153 | B172: LEONILSON DOS SANTOS SILVA | E172: =IF(OR(C172="", D172=""), 0, (D172-C172)*24) -> 0 | F172: =WEEKNUM(A172) -> 20 | G172: =MONTH(A172) -> 5 | H172: =YEAR(A172) -> 2026 | I172: =WEEKDAY(A172) -> 2
A173: 46153 | B173: ALEX FERREIRA DOS SANTOS | E173: =IF(OR(C173="", D173=""), 0, (D173-C173)*24) -> 0 | F173: =WEEKNUM(A173) -> 20 | G173: =MONTH(A173) -> 5 | H173: =YEAR(A173) -> 2026 | I173: =WEEKDAY(A173) -> 2
A174: 46153 | B174: FABIO MANOEL NERI | E174: =IF(OR(C174="", D174=""), 0, (D174-C174)*24) -> 0 | F174: =WEEKNUM(A174) -> 20 | G174: =MONTH(A174) -> 5 | H174: =YEAR(A174) -> 2026 | I174: =WEEKDAY(A174) -> 2
A175: 46153 | B175: FELIPE MONTEIRO BARROSO DE ANDRADE | E175: =IF(OR(C175="", D175=""), 0, (D175-C175)*24) -> 0 | F175: =WEEKNUM(A175) -> 20 | G175: =MONTH(A175) -> 5 | H175: =YEAR(A175) -> 2026 | I175: =WEEKDAY(A175) -> 2
A176: 46153 | B176: LUCAS OLIVEIRA DA SILVA | E176: =IF(OR(C176="", D176=""), 0, (D176-C176)*24) -> 0 | F176: =WEEKNUM(A176) -> 20 | G176: =MONTH(A176) -> 5 | H176: =YEAR(A176) -> 2026 | I176: =WEEKDAY(A176) -> 2
A177: 46153 | B177: DAVID APOLINARIO FRANCISCO | E177: =IF(OR(C177="", D177=""), 0, (D177-C177)*24) -> 0 | F177: =WEEKNUM(A177) -> 20 | G177: =MONTH(A177) -> 5 | H177: =YEAR(A177) -> 2026 | I177: =WEEKDAY(A177) -> 2
A178: 46154 | B178: LEONILSON DOS SANTOS SILVA | E178: =IF(OR(C178="", D178=""), 0, (D178-C178)*24) -> 0 | F178: =WEEKNUM(A178) -> 20 | G178: =MONTH(A178) -> 5 | H178: =YEAR(A178) -> 2026 | I178: =WEEKDAY(A178) -> 3
A179: 46154 | B179: ALEX FERREIRA DOS SANTOS | E179: =IF(OR(C179="", D179=""), 0, (D179-C179)*24) -> 0 | F179: =WEEKNUM(A179) -> 20 | G179: =MONTH(A179) -> 5 | H179: =YEAR(A179) -> 2026 | I179: =WEEKDAY(A179) -> 3
A180: 46154 | B180: FABIO MANOEL NERI | E180: =IF(OR(C180="", D180=""), 0, (D180-C180)*24) -> 0 | F180: =WEEKNUM(A180) -> 20 | G180: =MONTH(A180) -> 5 | H180: =YEAR(A180) -> 2026 | I180: =WEEKDAY(A180) -> 3
A181: 46154 | B181: FELIPE MONTEIRO BARROSO DE ANDRADE | E181: =IF(OR(C181="", D181=""), 0, (D181-C181)*24) -> 0 | F181: =WEEKNUM(A181) -> 20 | G181: =MONTH(A181) -> 5 | H181: =YEAR(A181) -> 2026 | I181: =WEEKDAY(A181) -> 3
A182: 46154 | B182: LUCAS OLIVEIRA DA SILVA | E182: =IF(OR(C182="", D182=""), 0, (D182-C182)*24) -> 0 | F182: =WEEKNUM(A182) -> 20 | G182: =MONTH(A182) -> 5 | H182: =YEAR(A182) -> 2026 | I182: =WEEKDAY(A182) -> 3
A183: 46154 | B183: DAVID APOLINARIO FRANCISCO | E183: =IF(OR(C183="", D183=""), 0, (D183-C183)*24) -> 0 | F183: =WEEKNUM(A183) -> 20 | G183: =MONTH(A183) -> 5 | H183: =YEAR(A183) -> 2026 | I183: =WEEKDAY(A183) -> 3
... A225: 46161 | B225: DAVID APOLINARIO FRANCISCO | E225: =IF(OR(C225="", D225=""), 0, (D225-C225)*24) -> 0 | F225: =WEEKNUM(A225) -> 21 | G225: =MONTH(A225) -> 5 | H225: =YEAR(A225) -> 2026 | I225: =WEEKDAY(A225) -> 3
E226: =IF(OR(C226="", D226=""), 0, (D226-C226)*24) -> 0 | F226: =WEEKNUM(A226) -> 0 | G226: =MONTH(A226) -> 1 | H226: =YEAR(A226) -> 1900 | I226: =WEEKDAY(A226) -> 7
E227: =IF(OR(C227="", D227=""), 0, (D227-C227)*24) -> 0 | F227: =WEEKNUM(A227) -> 0 | G227: =MONTH(A227) -> 1 | H227: =YEAR(A227) -> 1900 | I227: =WEEKDAY(A227) -> 7
E228: =IF(OR(C228="", D228=""), 0, (D228-C228)*24) -> 0 | F228: =WEEKNUM(A228) -> 0 | G228: =MONTH(A228) -> 1 | H228: =YEAR(A228) -> 1900 | I228: =WEEKDAY(A228) -> 7
E229: =IF(OR(C229="", D229=""), 0, (D229-C229)*24) -> 0 | F229: =WEEKNUM(A229) -> 0 | G229: =MONTH(A229) -> 1 | H229: =YEAR(A229) -> 1900 | I229: =WEEKDAY(A229) -> 7
E230: =IF(OR(C230="", D230=""), 0, (D230-C230)*24) -> 0 | F230: =WEEKNUM(A230) -> 0 | G230: =MONTH(A230) -> 1 | H230: =YEAR(A230) -> 1900 | I230: =WEEKDAY(A230) -> 7
E231: =IF(OR(C231="", D231=""), 0, (D231-C231)*24) -> 0 | F231: =WEEKNUM(A231) -> 0 | G231: =MONTH(A231) -> 1 | H231: =YEAR(A231) -> 1900 | I231: =WEEKDAY(A231) -> 7
E232: =IF(OR(C232="", D232=""), 0, (D232-C232)*24) -> 0 | F232: =WEEKNUM(A232) -> 0 | G232: =MONTH(A232) -> 1 | H232: =YEAR(A232) -> 1900 | I232: =WEEKDAY(A232) -> 7
E233: =IF(OR(C233="", D233=""), 0, (D233-C233)*24) -> 0 | F233: =WEEKNUM(A233) -> 0 | G233: =MONTH(A233) -> 1 | H233: =YEAR(A233) -> 1900 | I233: =WEEKDAY(A233) -> 7
E234: =IF(OR(C234="", D234=""), 0, (D234-C234)*24) -> 0 | F234: =WEEKNUM(A234) -> 0 | G234: =MONTH(A234) -> 1 | H234: =YEAR(A234) -> 1900 | I234: =WEEKDAY(A234) -> 7
E235: =IF(OR(C235="", D235=""), 0, (D235-C235)*24) -> 0 | F235: =WEEKNUM(A235) -> 0 | G235: =MONTH(A235) -> 1 | H235: =YEAR(A235) -> 1900 | I235: =WEEKDAY(A235) -> 7
E236: =IF(OR(C236="", D236=""), 0, (D236-C236)*24) -> 0 | F236: =WEEKNUM(A236) -> 0 | G236: =MONTH(A236) -> 1 | H236: =YEAR(A236) -> 1900 | I236: =WEEKDAY(A236) -> 7
E237: =IF(OR(C237="", D237=""), 0, (D237-C237)*24) -> 0 | F237: =WEEKNUM(A237) -> 0 | G237: =MONTH(A237) -> 1 | H237: =YEAR(A237) -> 1900 | I237: =WEEKDAY(A237) -> 7
... E256: =IF(OR(C256="", D256=""), 0, (D256-C256)*24) -> 0 | F256: =WEEKNUM(A256) -> 0 | G256: =MONTH(A256) -> 1 | H256: =YEAR(A256) -> 1900 | I256: =WEEKDAY(A256) -> 7
...

Sheet Resumo
A1: Mês (Vazio = Todos): | C1: Ano (Vazio = Todos): | E1: Semana (Vazio = Todas):
A3: COMO USAR: Apague os números acima para ver a SOMA TOTAL de todos os meses/semanas.
A5: Funcionário | B5: Segunda | C5: Terça | D5: Quarta | E5: Quinta | F5: Sexta | G5: Sábado | H5: Domingo | I5: Total Filtrado | J5: Soma Total Geral | K5: Dias Trabalhados (Geral)
A6: ALEX FERREIRA DOS SANTOS | B6: =SUMIFS('Banco de Dados'!$E:$E,'Banco de Dados'!$B:$B,$A6,'Banco de Dados'!$G:$G,IF($B$1="",">0",$B$1),'Banco de Dados'!$H:$H,IF($D$1="",">0",$D$1),'Banco de Dados'!$F:$F,IF($F$1="",">0",$F$1),'Banco de Dados'!$I:$I,2) -> 50.505556 | C6: =SUMIFS('Banco de Dados'!$E:$E,'Banco de Dados'!$B:$B,$A6,'Banco de Dados'!$G:$G,IF($B$1="",">0",$B$1),'Banco de Dados'!$H:$H,IF($D$1="",">0",$D$1),'Banco de Dados'!$F:$F,IF($F$1="",">0",$F$1),'Banco de Dados'!$I:$I,3) -> 27.644167 | D6: =SUMIFS('Banco de Dados'!$E:$E,'Banco de Dados'!$B:$B,$A6,'Banco de Dados'!$G:$G,IF($B$1="",">0",$B$1),'Banco de Dados'!$H:$H,IF($D$1="",">0",$D$1),'Banco de Dados'!$F:$F,IF($F$1="",">0",$F$1),'Banco de Dados'!$I:$I,4) -> 51.011111 | E6: =SUMIFS('Banco de Dados'!$E:$E,'Banco de Dados'!$B:$B,$A6,'Banco de Dados'!$G:$G,IF($B$1="",">0",$B$1),'Banco de Dados'!$H:$H,IF($D$1="",">0",$D$1),'Banco de Dados'!$F:$F,IF($F$1="",">0",$F$1),'Banco de Dados'!$I:$I,5) -> 48.453333 | F6: =SUMIFS('Banco de Dados'!$E:$E,'Banco de Dados'!$B:$B,$A6,'Banco de Dados'!$G:$G,IF($B$1="",">0",$B$1),'Banco de Dados'!$H:$H,IF($D$1="",">0",$D$1),'Banco de Dados'!$F:$F,IF($F$1="",">0",$F$1),'Banco de Dados'!$I:$I,6) -> 52.353611 | G6: =SUMIFS('Banco de Dados'!$E:$E,'Banco de Dados'!$B:$B,$A6,'Banco de Dados'!$G:$G,IF($B$1="",">0",$B$1),'Banco de Dados'!$H:$H,IF($D$1="",">0",$D$1),'Banco de Dados'!$F:$F,IF($F$1="",">0",$F$1),'Banco de Dados'!$I:$I,7) -> 32.21 | H6: =SUMIFS('Banco de Dados'!$E:$E,'Banco de Dados'!$B:$B,$A6,'Banco de Dados'!$G:$G,IF($B$1="",">0",$B$1),'Banco de Dados'!$H:$H,IF($D$1="",">0",$D$1),'Banco de Dados'!$F:$F,IF($F$1="",">0",$F$1),'Banco de Dados'!$I:$I,1) -> 0 | I6: =SUMIFS('Banco de Dados'!$E:$E,'Banco de Dados'!$B:$B,$A6,'Banco de Dados'!$G:$G,IF($B$1="",">0",$B$1),'Banco de Dados'!$H:$H,IF($D$1="",">0",$D$1),'Banco de Dados'!$F:$F,IF($F$1="",">0",$F$1)) -> 262.17778 | J6: =SUMIF('Banco de Dados'!$B$2:$B$4989, $A6, 'Banco de Dados'!$E$2:$E$4989) -> 262.17778 | K6: =COUNTIF('Banco de Dados'!$B$2:$B$4989, $A6) -> 39
A7: LUCAS J | B7: =SUMIFS('Banco de Dados'!$E:$E,'Banco de Dados'!$B:$B,$A7,'Banco de Dados'!$G:$G,IF($B$1="",">0",$B$1),'Banco de Dados'!$H:$H,IF($D$1="",">0",$D$1),'Banco de Dados'!$F:$F,IF($F$1="",">0",$F$1),'Banco de Dados'!$I:$I,2) -> 0 | C7: =SUMIFS('Banco de Dados'!$E:$E,'Banco de Dados'!$B:$B,$A7,'Banco de Dados'!$G:$G,IF($B$1="",">0",$B$1),'Banco de Dados'!$H:$H,IF($D$1="",">0",$D$1),'Banco de Dados'!$F:$F,IF($F$1="",">0",$F$1),'Banco de Dados'!$I:$I,3) -> 0 | D7: =SUMIFS('Banco de Dados'!$E:$E,'Banco de Dados'!$B:$B,$A7,'Banco de Dados'!$G:$G,IF($B$1="",">0",$B$1),'Banco de Dados'!$H:$H,IF($D$1="",">0",$D$1),'Banco de Dados'!$F:$F,IF($F$1="",">0",$F$1),'Banco de Dados'!$I:$I,4) -> 0 | E7: =SUMIFS('Banco de Dados'!$E:$E,'Banco de Dados'!$B:$B,$A7,'Banco de Dados'!$G:$G,IF($B$1="",">0",$B$1),'Banco de Dados'!$H:$H,IF($D$1="",">0",$D$1),'Banco de Dados'!$F:$F,IF($F$1="",">0",$F$1),'Banco de Dados'!$I:$I,5) -> 0 | F7: =SUMIFS('Banco de Dados'!$E:$E,'Banco de Dados'!$B:$B,$A7,'Banco de Dados'!$G:$G,IF($B$1="",">0",$B$1),'Banco de Dados'!$H:$H,IF($D$1="",">0",$D$1),'Banco de Dados'!$F:$F,IF($F$1="",">0",$F$1),'Banco de Dados'!$I:$I,6) -> 0 | G7: =SUMIFS('Banco de Dados'!$E:$E,'Banco de Dados'!$B:$B,$A7,'Banco de Dados'!$G:$G,IF($B$1="",">0",$B$1),'Banco de Dados'!$H:$H,IF($D$1="",">0",$D$1),'Banco de Dados'!$F:$F,IF($F$1="",">0",$F$1),'Banco de Dados'!$I:$I,7) -> 0 | H7: =SUMIFS('Banco de Dados'!$E:$E,'Banco de Dados'!$B:$B,$A7,'Banco de Dados'!$G:$G,IF($B$1="",">0",$B$1),'Banco de Dados'!$H:$H,IF($D$1="",">0",$D$1),'Banco de Dados'!$F:$F,IF($F$1="",">0",$F$1),'Banco de Dados'!$I:$I,1) -> 0 | I7: =SUMIFS('Banco de Dados'!$E:$E,'Banco de Dados'!$B:$B,$A7,'Banco de Dados'!$G:$G,IF($B$1="",">0",$B$1),'Banco de Dados'!$H:$H,IF($D$1="",">0",$D$1),'Banco de Dados'!$F:$F,IF($F$1="",">0",$F$1)) -> 0 | J7: =SUMIF('Banco de Dados'!$B$2:$B$4989, $A7, 'Banco de Dados'!$E$2:$E$4989) -> 0 | K7: =COUNTIF('Banco de Dados'!$B$2:$B$4989, $A7) -> 0
A8: LEONARDO LADENTHIN MAGALHAES | B8: =SUMIFS('Banco de Dados'!$E:$E,'Banco de Dados'!$B:$B,$A8,'Banco de Dados'!$G:$G,IF($B$1="",">0",$B$1),'Banco de Dados'!$H:$H,IF($D$1="",">0",$D$1),'Banco de Dados'!$F:$F,IF($F$1="",">0",$F$1),'Banco de Dados'!$I:$I,2) -> 0 | C8: =SUMIFS('Banco de Dados'!$E:$E,'Banco de Dados'!$B:$B,$A8,'Banco de Dados'!$G:$G,IF($B$1="",">0",$B$1),'Banco de Dados'!$H:$H,IF($D$1="",">0",$D$1),'Banco de Dados'!$F:$F,IF($F$1="",">0",$F$1),'Banco de Dados'!$I:$I,3) -> 0 | D8: =SUMIFS('Banco de Dados'!$E:$E,'Banco de Dados'!$B:$B,$A8,'Banco de Dados'!$G:$G,IF($B$1="",">0",$B$1),'Banco de Dados'!$H:$H,IF($D$1="",">0",$D$1),'Banco de Dados'!$F:$F,IF($F$1="",">0",$F$1),'Banco de Dados'!$I:$I,4) -> 0 | E8: =SUMIFS('Banco de Dados'!$E:$E,'Banco de Dados'!$B:$B,$A8,'Banco de Dados'!$G:$G,IF($B$1="",">0",$B$1),'Banco de Dados'!$H:$H,IF($D$1="",">0",$D$1),'Banco de Dados'!$F:$F,IF($F$1="",">0",$F$1),'Banco de Dados'!$I:$I,5) -> 0 | F8: =SUMIFS('Banco de Dados'!$E:$E,'Banco de Dados'!$B:$B,$A8,'Banco de Dados'!$G:$G,IF($B$1="",">0",$B$1),'Banco de Dados'!$H:$H,IF($D$1="",">0",$D$1),'Banco de Dados'!$F:$F,IF($F$1="",">0",$F$1),'Banco de Dados'!$I:$I,6) -> 0 | G8: =SUMIFS('Banco de Dados'!$E:$E,'Banco de Dados'!$B:$B,$A8,'Banco de Dados'!$G:$G,IF($B$1="",">0",$B$1),'Banco de Dados'!$H:$H,IF($D$1="",">0",$D$1),'Banco de Dados'!$F:$F,IF($F$1="",">0",$F$1),'Banco de Dados'!$I:$I,7) -> 0 | H8: =SUMIFS('Banco de Dados'!$E:$E,'Banco de Dados'!$B:$B,$A8,'Banco de Dados'!$G:$G,IF($B$1="",">0",$B$1),'Banco de Dados'!$H:$H,IF($D$1="",">0",$D$1),'Banco de Dados'!$F:$F,IF($F$1="",">0",$F$1),'Banco de Dados'!$I:$I,1) -> 0 | I8: =SUMIFS('Banco de Dados'!$E:$E,'Banco de Dados'!$B:$B,$A8,'Banco de Dados'!$G:$G,IF($B$1="",">0",$B$1),'Banco de Dados'!$H:$H,IF($D$1="",">0",$D$1),'Banco de Dados'!$F:$F,IF($F$1="",">0",$F$1)) -> 0 | J8: =SUMIF('Banco de Dados'!$B$2:$B$4989, $A8, 'Banco de Dados'!$E$2:$E$4989) -> 0 | K8: =COUNTIF('Banco de Dados'!$B$2:$B$4989, $A8) -> 0
A9: DAVID APOLINARIO FRANCISCO | B9: =SUMIFS('Banco de Dados'!$E:$E,'Banco de Dados'!$B:$B,$A9,'Banco de Dados'!$G:$G,IF($B$1="",">0",$B$1),'Banco de Dados'!$H:$H,IF($D$1="",">0",$D$1),'Banco de Dados'!$F:$F,IF($F$1="",">0",$F$1),'Banco de Dados'!$I:$I,2) -> 39.922778 | C9: =SUMIFS('Banco de Dados'!$E:$E,'Banco de Dados'!$B:$B,$A9,'Banco de Dados'!$G:$G,IF($B$1="",">0",$B$1),'Banco de Dados'!$H:$H,IF($D$1="",">0",$D$1),'Banco de Dados'!$F:$F,IF($F$1="",">0",$F$1),'Banco de Dados'!$I:$I,3) -> 30.363611 | D9: =SUMIFS('Banco de Dados'!$E:$E,'Banco de Dados'!$B:$B,$A9,'Banco de Dados'!$G:$G,IF($B$1="",">0",$B$1),'Banco de Dados'!$H:$H,IF($D$1="",">0",$D$1),'Banco de Dados'!$F:$F,IF($F$1="",">0",$F$1),'Banco de Dados'!$I:$I,4) -> 43.836389 | E9: =SUMIFS('Banco de Dados'!$E:$E,'Banco de Dados'!$B:$B,$A9,'Banco de Dados'!$G:$G,IF($B$1="",">0",$B$1),'Banco de Dados'!$H:$H,IF($D$1="",">0",$D$1),'Banco de Dados'!$F:$F,IF($F$1="",">0",$F$1),'Banco de Dados'!$I:$I,5) -> 29.426389 | F9: =SUMIFS('Banco de Dados'!$E:$E,'Banco de Dados'!$B:$B,$A9,'Banco de Dados'!$G:$G,IF($B$1="",">0",$B$1),'Banco de Dados'!$H:$H,IF($D$1="",">0",$D$1),'Banco de Dados'!$F:$F,IF($F$1="",">0",$F$1),'Banco de Dados'!$I:$I,6) -> 31.985556 | G9: =SUMIFS('Banco de Dados'!$E:$E,'Banco de Dados'!$B:$B,$A9,'Banco de Dados'!$G:$G,IF($B$1="",">0",$B$1),'Banco de Dados'!$H:$H,IF($D$1="",">0",$D$1),'Banco de Dados'!$F:$F,IF($F$1="",">0",$F$1),'Banco de Dados'!$I:$I,7) -> 8.6858333 | H9: =SUMIFS('Banco de Dados'!$E:$E,'Banco de Dados'!$B:$B,$A9,'Banco de Dados'!$G:$G,IF($B$1="",">0",$B$1),'Banco de Dados'!$H:$H,IF($D$1="",">0",$D$1),'Banco de Dados'!$F:$F,IF($F$1="",">0",$F$1),'Banco de Dados'!$I:$I,1) -> 0 | I9: =SUMIFS('Banco de Dados'!$E:$E,'Banco de Dados'!$B:$B,$A9,'Banco de Dados'!$G:$G,IF($B$1="",">0",$B$1),'Banco de Dados'!$H:$H,IF($D$1="",">0",$D$1),'Banco de Dados'!$F:$F,IF($F$1="",">0",$F$1)) -> 184.22056 | J9: =SUMIF('Banco de Dados'!$B$2:$B$4989, $A9, 'Banco de Dados'!$E$2:$E$4989) -> 184.22056 | K9: =COUNTIF('Banco de Dados'!$B$2:$B$4989, $A9) -> 37
A10: FABIO MANOEL NERI | B10: =SUMIFS('Banco de Dados'!$E:$E,'Banco de Dados'!$B:$B,$A10,'Banco de Dados'!$G:$G,IF($B$1="",">0",$B$1),'Banco de Dados'!$H:$H,IF($D$1="",">0",$D$1),'Banco de Dados'!$F:$F,IF($F$1="",">0",$F$1),'Banco de Dados'!$I:$I,2) -> 38.431667 | C10: =SUMIFS('Banco de Dados'!$E:$E,'Banco de Dados'!$B:$B,$A10,'Banco de Dados'!$G:$G,IF($B$1="",">0",$B$1),'Banco de Dados'!$H:$H,IF($D$1="",">0",$D$1),'Banco de Dados'!$F:$F,IF($F$1="",">0",$F$1),'Banco de Dados'!$I:$I,3) -> 37.668611 | D10: =SUMIFS('Banco de Dados'!$E:$E,'Banco de Dados'!$B:$B,$A10,'Banco de Dados'!$G:$G,IF($B$1="",">0",$B$1),'Banco de Dados'!$H:$H,IF($D$1="",">0",$D$1),'Banco de Dados'!$F:$F,IF($F$1="",">0",$F$1),'Banco de Dados'!$I:$I,4) -> 51.708056 | E10: =SUMIFS('Banco de Dados'!$E:$E,'Banco de Dados'!$B:$B,$A10,'Banco de Dados'!$G:$G,IF($B$1="",">0",$B$1),'Banco de Dados'!$H:$H,IF($D$1="",">0",$D$1),'Banco de Dados'!$F:$F,IF($F$1="",">0",$F$1),'Banco de Dados'!$I:$I,5) -> 54.155833 | F10: =SUMIFS('Banco de Dados'!$E:$E,'Banco de Dados'!$B:$B,$A10,'Banco de Dados'!$G:$G,IF($B$1="",">0",$B$1),'Banco de Dados'!$H:$H,IF($D$1="",">0",$D$1),'Banco de Dados'!$F:$F,IF($F$1="",">0",$F$1),'Banco de Dados'!$I:$I,6) -> 46.069444 | G10: =SUMIFS('Banco de Dados'!$E:$E,'Banco de Dados'!$B:$B,$A10,'Banco de Dados'!$G:$G,IF($B$1="",">0",$B$1),'Banco de Dados'!$H:$H,IF($D$1="",">0",$D$1),'Banco de Dados'!$F:$F,IF($F$1="",">0",$F$1),'Banco de Dados'!$I:$I,7) -> 26.78 | H10: =SUMIFS('Banco de Dados'!$E:$E,'Banco de Dados'!$B:$B,$A10,'Banco de Dados'!$G:$G,IF($B$1="",">0",$B$1),'Banco de Dados'!$H:$H,IF($D$1="",">0",$D$1),'Banco de Dados'!$F:$F,IF($F$1="",">0",$F$1),'Banco de Dados'!$I:$I,1) -> 0 | I10: =SUMIFS('Banco de Dados'!$E:$E,'Banco de Dados'!$B:$B,$A10,'Banco de Dados'!$G:$G,IF($B$1="",">0",$B$1),'Banco de Dados'!$H:$H,IF($D$1="",">0",$D$1),'Banco de Dados'!$F:$F,IF($F$1="",">0",$F$1)) -> 254.81361 | J10: =SUMIF('Banco de Dados'!$B$2:$B$4989, $A10, 'Banco de Dados'!$E$2:$E$4989) -> 254.81361 | K10: =COUNTIF('Banco de Dados'!$B$2:$B$4989, $A10) -> 37
A11: FELIPE MONTEIRO BARROSO DE ANDRADE | B11: =SUMIFS('Banco de Dados'!$E:$E,'Banco de Dados'!$B:$B,$A11,'Banco de Dados'!$G:$G,IF($B$1="",">0",$B$1),'Banco de Dados'!$H:$H,IF($D$1="",">0",$D$1),'Banco de Dados'!$F:$F,IF($F$1="",">0",$F$1),'Banco de Dados'!$I:$I,2) -> 35.877778 | C11: =SUMIFS('Banco de Dados'!$E:$E,'Banco de Dados'!$B:$B,$A11,'Banco de Dados'!$G:$G,IF($B$1="",">0",$B$1),'Banco de Dados'!$H:$H,IF($D$1="",">0",$D$1),'Banco de Dados'!$F:$F,IF($F$1="",">0",$F$1),'Banco de Dados'!$I:$I,3) -> 42.036111 | D11: =SUMIFS('Banco de Dados'!$E:$E,'Banco de Dados'!$B:$B,$A11,'Banco de Dados'!$G:$G,IF($B$1="",">0",$B$1),'Banco de Dados'!$H:$H,IF($D$1="",">0",$D$1),'Banco de Dados'!$F:$F,IF($F$1="",">0",$F$1),'Banco de Dados'!$I:$I,4) -> 45.021667 | E11: =SUMIFS('Banco de Dados'!$E:$E,'Banco de Dados'!$B:$B,$A11,'Banco de Dados'!$G:$G,IF($B$1="",">0",$B$1),'Banco de Dados'!$H:$H,IF($D$1="",">0",$D$1),'Banco de Dados'!$F:$F,IF($F$1="",">0",$F$1),'Banco de Dados'!$I:$I,5) -> 42.961389 | F11: =SUMIFS('Banco de Dados'!$E:$E,'Banco de Dados'!$B:$B,$A11,'Banco de Dados'!$G:$G,IF($B$1="",">0",$B$1),'Banco de Dados'!$H:$H,IF($D$1="",">0",$D$1),'Banco de Dados'!$F:$F,IF($F$1="",">0",$F$1),'Banco de Dados'!$I:$I,6) -> 31.006111 | G11: =SUMIFS('Banco de Dados'!$E:$E,'Banco de Dados'!$B:$B,$A11,'Banco de Dados'!$G:$G,IF($B$1="",">0",$B$1),'Banco de Dados'!$H:$H,IF($D$1="",">0",$D$1),'Banco de Dados'!$F:$F,IF($F$1="",">0",$F$1),'Banco de Dados'!$I:$I,7) -> 36.32 | H11: =SUMIFS('Banco de Dados'!$E:$E,'Banco de Dados'!$B:$B,$A11,'Banco de Dados'!$G:$G,IF($B$1="",">0",$B$1),'Banco de Dados'!$H:$H,IF($D$1="",">0",$D$1),'Banco de Dados'!$F:$F,IF($F$1="",">0",$F$1),'Banco de Dados'!$I:$I,1) -> 0 | I11: =SUMIFS('Banco de Dados'!$E:$E,'Banco de Dados'!$B:$B,$A11,'Banco de Dados'!$G:$G,IF($B$1="",">0",$B$1),'Banco de Dados'!$H:$H,IF($D$1="",">0",$D$1),'Banco de Dados'!$F:$F,IF($F$1="",">0",$F$1)) -> 233.22306 | J11: =SUMIF('Banco de Dados'!$B$2:$B$4989, $A11, 'Banco de Dados'!$E$2:$E$4989) -> 233.22306 | K11: =COUNTIF('Banco de Dados'!$B$2:$B$4989, $A11) -> 36
A12: LEONILSON DOS SANTOS SILVA | B12: =SUMIFS('Banco de Dados'!$E:$E,'Banco de Dados'!$B:$B,$A12,'Banco de Dados'!$G:$G,IF($B$1="",">0",$B$1),'Banco de Dados'!$H:$H,IF($D$1="",">0",$D$1),'Banco de Dados'!$F:$F,IF($F$1="",">0",$F$1),'Banco de Dados'!$I:$I,2) -> 41.423611 | C12: =SUMIFS('Banco de Dados'!$E:$E,'Banco de Dados'!$B:$B,$A12,'Banco de Dados'!$G:$G,IF($B$1="",">0",$B$1),'Banco de Dados'!$H:$H,IF($D$1="",">0",$D$1),'Banco de Dados'!$F:$F,IF($F$1="",">0",$F$1),'Banco de Dados'!$I:$I,3) -> 41.363611 | D12: =SUMIFS('Banco de Dados'!$E:$E,'Banco de Dados'!$B:$B,$A12,'Banco de Dados'!$G:$G,IF($B$1="",">0",$B$1),'Banco de Dados'!$H:$H,IF($D$1="",">0",$D$1),'Banco de Dados'!$F:$F,IF($F$1="",">0",$F$1),'Banco de Dados'!$I:$I,4) -> 45.988611 | E12: =SUMIFS('Banco de Dados'!$E:$E,'Banco de Dados'!$B:$B,$A12,'Banco de Dados'!$G:$G,IF($B$1="",">0",$B$1),'Banco de Dados'!$H:$H,IF($D$1="",">0",$D$1),'Banco de Dados'!$F:$F,IF($F$1="",">0",$F$1),'Banco de Dados'!$I:$I,5) -> 51.200278 | F12: =SUMIFS('Banco de Dados'!$E:$E,'Banco de Dados'!$B:$B,$A12,'Banco de Dados'!$G:$G,IF($B$1="",">0",$B$1),'Banco de Dados'!$H:$H,IF($D$1="",">0",$D$1),'Banco de Dados'!$F:$F,IF($F$1="",">0",$F$1),'Banco de Dados'!$I:$I,6) -> 40.632778 | G12: =SUMIFS('Banco de Dados'!$E:$E,'Banco de Dados'!$B:$B,$A12,'Banco de Dados'!$G:$G,IF($B$1="",">0",$B$1),'Banco de Dados'!$H:$H,IF($D$1="",">0",$D$1),'Banco de Dados'!$F:$F,IF($F$1="",">0",$F$1),'Banco de Dados'!$I:$I,7) -> 24.441111 | H12: =SUMIFS('Banco de Dados'!$E:$E,'Banco de Dados'!$B:$B,$A12,'Banco de Dados'!$G:$G,IF($B$1="",">0",$B$1),'Banco de Dados'!$H:$H,IF($D$1="",">0",$D$1),'Banco de Dados'!$F:$F,IF($F$1="",">0",$F$1),'Banco de Dados'!$I:$I,1) -> 0 | I12: =SUMIFS('Banco de Dados'!$E:$E,'Banco de Dados'!$B:$B,$A12,'Banco de Dados'!$G:$G,IF($B$1="",">0",$B$1),'Banco de Dados'!$H:$H,IF($D$1="",">0",$D$1),'Banco de Dados'!$F:$F,IF($F$1="",">0",$F$1)) -> 245.05 | J12: =SUMIF('Banco de Dados'!$B$2:$B$4989, $A12, 'Banco de Dados'!$E$2:$E$4989) -> 245.05 | K12: =COUNTIF('Banco de Dados'!$B$2:$B$4989, $A12) -> 38
A13: LUCAS OLIVEIRA DA SILVA | B13: =SUMIFS('Banco de Dados'!$E:$E,'Banco de Dados'!$B:$B,$A13,'Banco de Dados'!$G:$G,IF($B$1="",">0",$B$1),'Banco de Dados'!$H:$H,IF($D$1="",">0",$D$1),'Banco de Dados'!$F:$F,IF($F$1="",">0",$F$1),'Banco de Dados'!$I:$I,2) -> 25.104444 | C13: =SUMIFS('Banco de Dados'!$E:$E,'Banco de Dados'!$B:$B,$A13,'Banco de Dados'!$G:$G,IF($B$1="",">0",$B$1),'Banco de Dados'!$H:$H,IF($D$1="",">0",$D$1),'Banco de Dados'!$F:$F,IF($F$1="",">0",$F$1),'Banco de Dados'!$I:$I,3) -> 37.879167 | D13: =SUMIFS('Banco de Dados'!$E:$E,'Banco de Dados'!$B:$B,$A13,'Banco de Dados'!$G:$G,IF($B$1="",">0",$B$1),'Banco de Dados'!$H:$H,IF($D$1="",">0",$D$1),'Banco de Dados'!$F:$F,IF($F$1="",">0",$F$1),'Banco de Dados'!$I:$I,4) -> 34.981111 | E13: =SUMIFS('Banco de Dados'!$E:$E,'Banco de Dados'!$B:$B,$A13,'Banco de Dados'!$G:$G,IF($B$1="",">0",$B$1),'Banco de Dados'!$H:$H,IF($D$1="",">0",$D$1),'Banco de Dados'!$F:$F,IF($F$1="",">0",$F$1),'Banco de Dados'!$I:$I,5) -> 29.728889 | F13: =SUMIFS('Banco de Dados'!$E:$E,'Banco de Dados'!$B:$B,$A13,'Banco de Dados'!$G:$G,IF($B$1="",">0",$B$1),'Banco de Dados'!$H:$H,IF($D$1="",">0",$D$1),'Banco de Dados'!$F:$F,IF($F$1="",">0",$F$1),'Banco de Dados'!$I:$I,6) -> 33.263611 | G13: =SUMIFS('Banco de Dados'!$E:$E,'Banco de Dados'!$B:$B,$A13,'Banco de Dados'!$G:$G,IF($B$1="",">0",$B$1),'Banco de Dados'!$H:$H,IF($D$1="",">0",$D$1),'Banco de Dados'!$F:$F,IF($F$1="",">0",$F$1),'Banco de Dados'!$I:$I,7) -> 24.255556 | H13: =SUMIFS('Banco de Dados'!$E:$E,'Banco de Dados'!$B:$B,$A13,'Banco de Dados'!$G:$G,IF($B$1="",">0",$B$1),'Banco de Dados'!$H:$H,IF($D$1="",">0",$D$1),'Banco de Dados'!$F:$F,IF($F$1="",">0",$F$1),'Banco de Dados'!$I:$I,1) -> 0 | I13: =SUMIFS('Banco de Dados'!$E:$E,'Banco de Dados'!$B:$B,$A13,'Banco de Dados'!$G:$G,IF($B$1="",">0",$B$1),'Banco de Dados'!$H:$H,IF($D$1="",">0",$D$1),'Banco de Dados'!$F:$F,IF($F$1="",">0",$F$1)) -> 185.21278 | J13: =SUMIF('Banco de Dados'!$B$2:$B$4989, $A13, 'Banco de Dados'!$E$2:$E$4989) -> 185.21278 | K13: =COUNTIF('Banco de Dados'!$B$2:$B$4989, $A13) -> 37
